Traceback (most recent call last):
  File "C:\Users\silve\anaconda3\lib\site-packages\jupyter_cache\executors\utils.py", line 58, in single_nb_execution
    executenb(
  File "C:\Users\silve\anaconda3\lib\site-packages\nbclient\client.py", line 1204, in execute
    return NotebookClient(nb=nb, resources=resources, km=km, **kwargs).execute()
  File "C:\Users\silve\anaconda3\lib\site-packages\nbclient\util.py", line 84, in wrapped
    return just_run(coro(*args, **kwargs))
  File "C:\Users\silve\anaconda3\lib\site-packages\nbclient\util.py", line 62, in just_run
    return loop.run_until_complete(coro)
  File "C:\Users\silve\anaconda3\lib\asyncio\base_events.py", line 649, in run_until_complete
    return future.result()
  File "C:\Users\silve\anaconda3\lib\site-packages\nbclient\client.py", line 663, in async_execute
    await self.async_execute_cell(
  File "C:\Users\silve\anaconda3\lib\site-packages\nbclient\client.py", line 965, in async_execute_cell
    await self._check_raise_for_error(cell, cell_index, exec_reply)
  File "C:\Users\silve\anaconda3\lib\site-packages\nbclient\client.py", line 862, in _check_raise_for_error
    raise CellExecutionError.from_cell_and_msg(cell, exec_reply_content)
nbclient.exceptions.CellExecutionError: An error occurred while executing the following cell:
------------------
array_split1 = np.array_split(array_x, 2)          # splits an array into n arrays by columns
print(array_split1)
print(np.shape(array_split1))

array_split2 = np.array_split(array_x, 2, axis=1)  # splits an array into n arrays by rows
print(array_split2)
print(np.shape(array_split2))

# np.hsplit(array_x, 2)
# np.vsplit(array_x, 2)
# np.dsplit(array_x, 2)
------------------

[1;31m---------------------------------------------------------------------------[0m
[1;31mAttributeError[0m                            Traceback (most recent call last)
File [1;32m~\anaconda3\lib\site-packages\numpy\core\fromnumeric.py:2033[0m, in [0;36mshape[1;34m(a)[0m
[0;32m   2032[0m [38;5;28;01mtry[39;00m:
[1;32m-> 2033[0m     result [38;5;241m=[39m [43ma[49m[38;5;241;43m.[39;49m[43mshape[49m
[0;32m   2034[0m [38;5;28;01mexcept[39;00m [38;5;167;01mAttributeError[39;00m:

[1;31mAttributeError[0m: 'list' object has no attribute 'shape'

During handling of the above exception, another exception occurred:

[1;31mValueError[0m                                Traceback (most recent call last)
Cell [1;32mIn[44], line 7[0m
[0;32m      5[0m array_split2 [38;5;241m=[39m np[38;5;241m.[39marray_split(array_x, [38;5;241m2[39m, axis[38;5;241m=[39m[38;5;241m1[39m)  [38;5;66;03m# splits an array into n arrays by rows[39;00m
[0;32m      6[0m [38;5;28mprint[39m(array_split2)
[1;32m----> 7[0m [38;5;28mprint[39m([43mnp[49m[38;5;241;43m.[39;49m[43mshape[49m[43m([49m[43marray_split2[49m[43m)[49m)

File [1;32m<__array_function__ internals>:200[0m, in [0;36mshape[1;34m(*args, **kwargs)[0m

File [1;32m~\anaconda3\lib\site-packages\numpy\core\fromnumeric.py:2035[0m, in [0;36mshape[1;34m(a)[0m
[0;32m   2033[0m     result [38;5;241m=[39m a[38;5;241m.[39mshape
[0;32m   2034[0m [38;5;28;01mexcept[39;00m [38;5;167;01mAttributeError[39;00m:
[1;32m-> 2035[0m     result [38;5;241m=[39m [43masarray[49m[43m([49m[43ma[49m[43m)[49m[38;5;241m.[39mshape
[0;32m   2036[0m [38;5;28;01mreturn[39;00m result

[1;31mValueError[0m: setting an array element with a sequence. The requested array has an inhomogeneous shape after 2 dimensions. The detected shape was (2, 2) + inhomogeneous part.
ValueError: setting an array element with a sequence. The requested array has an inhomogeneous shape after 2 dimensions. The detected shape was (2, 2) + inhomogeneous part.

