Traceback (most recent call last):
  File "C:\Users\silve\AppData\Roaming\jupyterlab-desktop\jlab_server\lib\site-packages\jupyter_cache\executors\utils.py", line 58, in single_nb_execution
    executenb(
  File "C:\Users\silve\AppData\Roaming\jupyterlab-desktop\jlab_server\lib\site-packages\nbclient\client.py", line 1305, in execute
    return NotebookClient(nb=nb, resources=resources, km=km, **kwargs).execute()
  File "C:\Users\silve\AppData\Roaming\jupyterlab-desktop\jlab_server\lib\site-packages\jupyter_core\utils\__init__.py", line 173, in wrapped
    return loop.run_until_complete(inner)
  File "C:\Users\silve\AppData\Roaming\jupyterlab-desktop\jlab_server\lib\asyncio\base_events.py", line 616, in run_until_complete
    return future.result()
  File "C:\Users\silve\AppData\Roaming\jupyterlab-desktop\jlab_server\lib\site-packages\nbclient\client.py", line 705, in async_execute
    await self.async_execute_cell(
  File "C:\Users\silve\AppData\Roaming\jupyterlab-desktop\jlab_server\lib\site-packages\nbclient\client.py", line 1058, in async_execute_cell
    await self._check_raise_for_error(cell, cell_index, exec_reply)
  File "C:\Users\silve\AppData\Roaming\jupyterlab-desktop\jlab_server\lib\site-packages\nbclient\client.py", line 914, in _check_raise_for_error
    raise CellExecutionError.from_cell_and_msg(cell, exec_reply_content)
nbclient.exceptions.CellExecutionError: An error occurred while executing the following cell:
------------------
acorr_ljungbox(candidate_model.resid2, lags=[2*7], return_df=True, model_df=4)  # model_df = p + q
------------------


[1;31m---------------------------------------------------------------------------[0m
[1;31mAttributeError[0m                            Traceback (most recent call last)
Cell [1;32mIn[13], line 1[0m
[1;32m----> 1[0m acorr_ljungbox([43mcandidate_model[49m[38;5;241;43m.[39;49m[43mresid2[49m, lags[38;5;241m=[39m[[38;5;241m2[39m[38;5;241m*[39m[38;5;241m7[39m], return_df[38;5;241m=[39m[38;5;28;01mTrue[39;00m, model_df[38;5;241m=[39m[38;5;241m4[39m)  [38;5;66;03m# model_df = p + q[39;00m

File [1;32m~\AppData\Roaming\jupyterlab-desktop\jlab_server\lib\site-packages\statsmodels\base\wrapper.py:34[0m, in [0;36mResultsWrapper.__getattribute__[1;34m(self, attr)[0m
[0;32m     31[0m [38;5;28;01mexcept[39;00m [38;5;167;01mAttributeError[39;00m:
[0;32m     32[0m     [38;5;28;01mpass[39;00m
[1;32m---> 34[0m obj [38;5;241m=[39m [38;5;28;43mgetattr[39;49m[43m([49m[43mresults[49m[43m,[49m[43m [49m[43mattr[49m[43m)[49m
[0;32m     35[0m data [38;5;241m=[39m results[38;5;241m.[39mmodel[38;5;241m.[39mdata
[0;32m     36[0m how [38;5;241m=[39m [38;5;28mself[39m[38;5;241m.[39m_wrap_attrs[38;5;241m.[39mget(attr)

[1;31mAttributeError[0m: 'SARIMAXResults' object has no attribute 'resid2'

